Workbook
Name cabcolor: [1]OrderForm!$R$15
Name cabcolor: [1]OrderForm!$R$15
Name cabcolor: [2]OrderForm!$Q$15
Name cabprice: [1]OrderForm!$R$16
Name cabprice: [1]OrderForm!$R$16
Name cabprice: [2]OrderForm!$Q$16
Name 物料: #REF!

Sheet Summary Sheet
A1: POWER 38 | L1: Enter information, then, Hide Columns "L" "M" & "N" once finished by selecting the columns and right-clicking, then select "hide columns"
A2: Product | B2: Unit Type | C2: Qty | D2: Unit Price | E2: Total | F2: Total Cabinets | G2: Trim Per Unit | H2: Total Trim | I2: Handles Per Unit | J2: Cabinet Hardware Count | L2: Cabinet Style: | M2: Frameless
A3: =IF(M2="Frameless", "Frameless", "Framed") -> Frameless | B3: 3B2B | C3: 26 | D3: =SUM('Unit Type'!G71:G72) -> 3514.1688 | E3: =C3*D3 -> 91368.389 | F3: ='Unit Type'!C74 -> 442 | G3: ='Unit Type'!C72 -> 27 | H3: =G3*C3 -> 702 | I3: ='Unit Type'!I71 -> 34 | J3: =I3*C3 -> 884 | L3: Cabinet Finish: | M3: Matte White
B4: 3B3BD | C4: 11 | D4: =SUM('Unit Type (2)'!G71:G72) -> 2736.7162 | E4: =C4*D4 -> 30103.878 | F4: ='Unit Type (2)'!C74 -> 154 | G4: ='Unit Type (2)'!C72 -> 19 | H4: =G4*C4 -> 209 | I4: ='Unit Type (2)'!I71 -> 27 | J4: =I4*C4 -> 297 | L4: Box Construction: | M4: Plywood
B5: 3B2B ANSI A | C5: 1 | D5: =SUM('Unit Type (3)'!G71:G72) -> 2578.7314 | E5: =C5*D5 -> 2578.7314 | F5: ='Unit Type (3)'!C74 -> 12 | G5: ='Unit Type (3)'!C72 -> 18 | H5: =G5*C5 -> 18 | I5: ='Unit Type (3)'!I71 -> 27 | J5: =I5*C5 -> 27 | L5: Price Margin: | M5: 0.2
D6: =SUM('Unit Type (4)'!G71:G72) -> 0 | E6: =C6*D6 -> 0 | F6: ='Unit Type (4)'!C74 -> 0 | G6: ='Unit Type (4)'!C72 -> 0 | H6: =G6*C6 -> 0 | I6: ='Unit Type (4)'!I71 -> 0 | J6: =I6*C6 -> 0 | L6: Factor: | M6: =IF('Summary Sheet'!M2:N2="Framed",VLOOKUP(M5,List!B20:C70,2,FALSE),IF('Summary Sheet'!M2:N2="Frameless",VLOOKUP(M5,List!B20:D70,3,FALSE),"Select Cabinet Style")) -> 0.162
D7: =SUM('Unit Type (5)'!G71:G72) -> 0 | E7: =C7*D7 -> 0 | F7: ='Unit Type (5)'!C74 -> 0 | G7: ='Unit Type (5)'!C72 -> 0 | H7: =G7*C7 -> 0 | I7: ='Unit Type (5)'!I71 -> 0 | J7: =I7*C7 -> 0
D8: =SUM('Unit Type (6)'!G71:G72) -> 0 | E8: =C8*D8 -> 0 | F8: ='Unit Type (6)'!C74 -> 0 | G8: ='Unit Type (6)'!C72 -> 0 | H8: =G8*C8 -> 0 | I8: ='Unit Type (6)'!I71 -> 0 | J8: =I8*C8 -> 0 | L8: Handle Price (Per Handle): | M8: 2.75
D9: =SUM('Unit Type (7)'!G71:G72) -> 0 | E9: =C9*D9 -> 0 | F9: ='Unit Type (7)'!C74 -> 0 | G9: ='Unit Type (7)'!C72 -> 0 | H9: =G9*C9 -> 0 | I9: ='Unit Type (7)'!I71 -> 0 | J9: =I9*C9 -> 0 | L9: Build Cost (Per Box): | M9: 20
D10: =SUM('Unit Type (8)'!G71:G72) -> 0 | E10: =C10*D10 -> 0 | F10: ='Unit Type (8)'!C74 -> 0 | G10: ='Unit Type (8)'!C72 -> 0 | H10: =G10*C10 -> 0 | I10: ='Unit Type (8)'!I71 -> 0 | J10: =I10*C10 -> 0 | L10: Shipping Per Unit: | M10: 125
D11: =SUM('Unit Type (9)'!G71:G72) -> 0 | E11: =C11*D11 -> 0 | F11: ='Unit Type (9)'!C74 -> 0 | G11: ='Unit Type (9)'!C72 -> 0 | H11: =G11*C11 -> 0 | I11: ='Unit Type (9)'!I71 -> 0 | J11: =I11*C11 -> 0
D12: =SUM('Unit Type (10)'!G71:G72) -> 0 | E12: =C12*D12 -> 0 | F12: ='Unit Type (10)'!C74 -> 0 | G12: ='Unit Type (10)'!C72 -> 0 | H12: =G12*C12 -> 0 | I12: ='Unit Type (10)'!I71 -> 0 | J12: =I12*C12 -> 0 | L12: Make a copy of this sheet before you begin. OPEN, then SAVE AS your project name. Then fire away! Start by filling out the unit type information, the Summary Sheet will populate as the unit types are completed. You only need to enter the "Unit Type" name and "QTY" on the summary sheet. Leave the "Unit Price", "Total", "Total Cabinets", and "Cabinet Hardware Count" fields alone.
D13: =SUM('Unit Type (11)'!G71:G72) -> 0 | E13: =C13*D13 -> 0 | F13: ='Unit Type (11)'!C74 -> 0 | G13: ='Unit Type (11)'!C72 -> 0 | H13: =G13*C13 -> 0 | I13: ='Unit Type (11)'!I71 -> 0 | J13: =I13*C13 -> 0
D14: =SUM('Unit Type (12)'!G71:G72) -> 0 | E14: =C14*D14 -> 0 | F14: ='Unit Type (12)'!C74 -> 0 | G14: ='Unit Type (12)'!C72 -> 0 | H14: =G14*C14 -> 0 | I14: ='Unit Type (12)'!I71 -> 0 | J14: =I14*C14 -> 0
D15: =SUM('Unit Type (13)'!G71:G72) -> 0 | E15: =C15*D15 -> 0 | F15: ='Unit Type (13)'!C74 -> 0 | G15: ='Unit Type (13)'!C72 -> 0 | H15: =G15*C15 -> 0 | I15: ='Unit Type (13)'!I71 -> 0 | J15: =I15*C15 -> 0
D16: =SUM('Unit Type (14)'!G71:G72) -> 0 | E16: =C16*D16 -> 0 | F16: ='Unit Type (14)'!C74 -> 0 | G16: ='Unit Type (14)'!C72 -> 0 | H16: =G16*C16 -> 0 | I16: ='Unit Type (14)'!I71 -> 0 | J16: =I16*C16 -> 0
D17: =SUM('Unit Type (15)'!G71:G72) -> 0 | E17: =C17*D17 -> 0 | F17: ='Unit Type (15)'!C74 -> 0 | G17: ='Unit Type (15)'!C72 -> 0 | H17: =G17*C17 -> 0 | I17: ='Unit Type (15)'!I71 -> 0 | J17: =I17*C17 -> 0
D18: =SUM('Unit Type (16)'!G71:G72) -> 0 | E18: =C18*D18 -> 0 | F18: ='Unit Type (16)'!C74 -> 0 | G18: ='Unit Type (16)'!C72 -> 0 | H18: =G18*C18 -> 0 | I18: ='Unit Type (16)'!I71 -> 0 | J18: =I18*C18 -> 0
D19: =SUM('Unit Type (17)'!G71:G72) -> 0 | E19: =C19*D19 -> 0 | F19: ='Unit Type (17)'!C74 -> 0 | G19: ='Unit Type (17)'!C72 -> 0 | H19: =G19*C19 -> 0 | I19: ='Unit Type (17)'!I71 -> 0 | J19: =I19*C19 -> 0
D20: =SUM('Unit Type (18)'!G71:G72) -> 0 | E20: =C20*D20 -> 0 | F20: ='Unit Type (18)'!C74 -> 0 | G20: ='Unit Type (18)'!C72 -> 0 | H20: =G20*C20 -> 0 | I20: ='Unit Type (18)'!I71 -> 0 | J20: =I20*C20 -> 0
D21: =SUM('Unit Type (19)'!G71:G72) -> 0 | E21: =C21*D21 -> 0 | F21: ='Unit Type (19)'!C74 -> 0 | G21: ='Unit Type (19)'!C72 -> 0 | H21: =G21*C21 -> 0 | I21: ='Unit Type (19)'!I71 -> 0 | J21: =I21*C21 -> 0
D22: =SUM('Unit Type (20)'!G71:G72) -> 0 | E22: =C22*D22 -> 0 | F22: ='Unit Type (20)'!C74 -> 0 | G22: ='Unit Type (20)'!C72 -> 0 | H22: =G22*C22 -> 0 | I22: ='Unit Type (20)'!I71 -> 0 | J22: =I22*C22 -> 0 | L22: You may hide any extra rows/columns of any extra unit types to make the document more succinct.
D23: =SUM('Unit Type (21)'!G71:G72) -> 0 | E23: =C23*D23 -> 0 | F23: ='Unit Type (21)'!C74 -> 0 | G23: ='Unit Type (21)'!C72 -> 0 | H23: =G23*C23 -> 0 | I23: ='Unit Type (21)'!I71 -> 0 | J23: =I23*C23 -> 0
D24: =SUM('Unit Type (22)'!G71:G72) -> 0 | E24: =C24*D24 -> 0 | F24: ='Unit Type (22)'!C74 -> 0 | G24: ='Unit Type (22)'!C72 -> 0 | H24: =G24*C24 -> 0 | I24: ='Unit Type (22)'!I71 -> 0 | J24: =I24*C24 -> 0
D25: =SUM('Unit Type (23)'!G71:G72) -> 0 | E25: =C25*D25 -> 0 | F25: ='Unit Type (23)'!C74 -> 0 | G25: ='Unit Type (23)'!C72 -> 0 | H25: =G25*C25 -> 0 | I25: ='Unit Type (23)'!I71 -> 0 | J25: =I25*C25 -> 0
D26: =SUM('Unit Type (24)'!G71:G72) -> 0 | E26: =C26*D26 -> 0 | F26: ='Unit Type (24)'!C74 -> 0 | G26: ='Unit Type (24)'!C72 -> 0 | H26: =G26*C26 -> 0 | I26: ='Unit Type (24)'!I71 -> 0 | J26: =I26*C26 -> 0
D27: =SUM('Unit Type (25)'!G71:G72) -> 0 | E27: =C27*D27 -> 0 | F27: ='Unit Type (25)'!C74 -> 0 | G27: ='Unit Type (25)'!C72 -> 0 | H27: =G27*C27 -> 0 | I27: ='Unit Type (25)'!I71 -> 0 | J27: =I27*C27 -> 0
D28: =SUM('Unit Type (26)'!G71:G72) -> 0 | E28: =C28*D28 -> 0 | F28: ='Unit Type (26)'!C74 -> 0 | G28: ='Unit Type (26)'!C72 -> 0 | H28: =G28*C28 -> 0 | I28: ='Unit Type (26)'!I71 -> 0 | J28: =I28*C28 -> 0
D29: =SUM('Unit Type (27)'!G71:G72) -> 0 | E29: =C29*D29 -> 0 | F29: ='Unit Type (27)'!C74 -> 0 | G29: ='Unit Type (27)'!C72 -> 0 | H29: =G29*C29 -> 0 | I29: ='Unit Type (27)'!I71 -> 0 | J29: =I29*C29 -> 0
D30: =SUM('Unit Type (28)'!G71:G72) -> 0 | E30: =C30*D30 -> 0 | F30: ='Unit Type (28)'!C74 -> 0 | G30: ='Unit Type (28)'!C72 -> 0 | H30: =G30*C30 -> 0 | I30: ='Unit Type (28)'!I71 -> 0 | J30: =I30*C30 -> 0
D31: =SUM('Unit Type (29)'!G71:G72) -> 0 | E31: =C31*D31 -> 0 | F31: ='Unit Type (29)'!C74 -> 0 | G31: ='Unit Type (29)'!C72 -> 0 | H31: =G31*C31 -> 0 | I31: ='Unit Type (29)'!I71 -> 0 | J31: =I31*C31 -> 0
D32: =SUM('Unit Type (30)'!G71:G72) -> 0 | E32: =C32*D32 -> 0 | F32: ='Unit Type (30)'!C74 -> 0 | G32: ='Unit Type (30)'!C72 -> 0 | H32: =G32*C32 -> 0 | I32: ='Unit Type (30)'!I71 -> 0 | J32: =I32*C32 -> 0
D33: =SUM('Unit Type (31)'!G71:G72) -> 0 | E33: =C33*D33 -> 0 | F33: ='Unit Type (31)'!C74 -> 0 | G33: ='Unit Type (31)'!C72 -> 0 | H33: =G33*C33 -> 0 | I33: ='Unit Type (31)'!I71 -> 0 | J33: =I33*C33 -> 0
D34: =SUM('Unit Type (32)'!G71:G72) -> 0 | E34: =C34*D34 -> 0 | F34: ='Unit Type (32)'!C74 -> 0 | G34: ='Unit Type (32)'!C72 -> 0 | H34: =G34*C34 -> 0 | I34: ='Unit Type (32)'!I71 -> 0 | J34: =I34*C34 -> 0
D35: =SUM('Unit Type (33)'!G71:G72) -> 0 | E35: =C35*D35 -> 0 | F35: ='Unit Type (33)'!C74 -> 0 | G35: ='Unit Type (33)'!C72 -> 0 | H35: =G35*C35 -> 0 | I35: ='Unit Type (33)'!I71 -> 0 | J35: =I35*C35 -> 0
D36: =SUM('Unit Type (34)'!G71:G72) -> 0 | E36: =C36*D36 -> 0 | F36: ='Unit Type (34)'!C74 -> 0 | G36: ='Unit Type (34)'!C72 -> 0 | H36: =G36*C36 -> 0 | I36: ='Unit Type (34)'!I71 -> 0 | J36: =I36*C36 -> 0
D37: =SUM('Unit Type (35)'!G71:G72) -> 0 | E37: =C37*D37 -> 0 | F37: ='Unit Type (35)'!C74 -> 0 | G37: ='Unit Type (35)'!C72 -> 0 | H37: =G37*C37 -> 0 | I37: ='Unit Type (35)'!I71 -> 0 | J37: =I37*C37 -> 0
D38: =SUM('Unit Type (36)'!G71:G72) -> 0 | E38: =C38*D38 -> 0 | F38: ='Unit Type (36)'!C74 -> 0 | G38: ='Unit Type (36)'!C72 -> 0 | H38: =G38*C38 -> 0 | I38: ='Unit Type (36)'!I71 -> 0 | J38: =I38*C38 -> 0
D39: =SUM('Unit Type (37)'!G71:G72) -> 0 | E39: =C39*D39 -> 0 | F39: ='Unit Type (37)'!C74 -> 0 | G39: ='Unit Type (37)'!C72 -> 0 | H39: =G39*C39 -> 0 | I39: ='Unit Type (37)'!I71 -> 0 | J39: =I39*C39 -> 0
D40: =SUM('Unit Type (38)'!G71:G72) -> 0 | E40: =C40*D40 -> 0 | F40: ='Unit Type (38)'!C74 -> 0 | G40: ='Unit Type (38)'!C72 -> 0 | H40: =G40*C40 -> 0 | I40: ='Unit Type (38)'!I71 -> 0 | J40: =I40*C40 -> 0
...

Sheet Framed Catalog List Price
C2: ONYX BLACK | E2: WHITE SHAKER | G2: ESPRESSO SHAKER | I2: SIGNATURE BLUE | K2: Grey Shaker | M2: Uptown White | O2: Modern Slate | Q2: Dark Green Slim Shaker
A3: Description | B3: Cabinet Name | C3: List Price | D3: Inventory Code | E3: List Price | F3: Inventory Code | G3: List Price | H3: Inventory Code | I3: List Price | J3: Inventory Code | K3: List Price | L3: Inventory Code | M3: List Price | N3: Inventory Code | O3: List Price | P3: Inventory Code | Q3: List Price | R3: Inventory Code
A4: Base Cabinets with Drawer, 24" Depth
A5: 9" Base Cabinet: 1 Door & 1 Drawer | B5: B09 | C5: 476 | D5: =CONCATENATE("ONB-",B5) -> ONB-B09 | E5: 433 | F5: =CONCATENATE("WHS-",B5) -> WHS-B09 | G5: 476 | H5: =CONCATENATE("ESS-",B5) -> ESS-B09 | I5: 476 | J5: =CONCATENATE("SIB-",B5) -> SIB-B09 | K5: 433 | L5: =CONCATENATE("GRS-",B5) -> GRS-B09 | M5: 476 | N5: =CONCATENATE("UPB-",B5) -> UPB-B09 | O5: 476 | P5: =CONCATENATE("MSL-",B5) -> MSL-B09 | Q5: 476 | R5: =CONCATENATE("DGS-",B5) -> DGS-B09 | S5: 2
A6: 12" Base Cabinet: 1 Door & 1 Drawer | B6: B12 | C6: 618 | D6: =CONCATENATE("ONB-",B6) -> ONB-B12 | E6: 562 | F6: =CONCATENATE("WHS-",B6) -> WHS-B12 | G6: 618 | H6: =CONCATENATE("ESS-",B6) -> ESS-B12 | I6: 618 | J6: =CONCATENATE("SIB-",B6) -> SIB-B12 | K6: 562 | L6: =CONCATENATE("GRS-",B6) -> GRS-B12 | M6: 618 | N6: =CONCATENATE("UPB-",B6) -> UPB-B12 | O6: 618 | P6: =CONCATENATE("MSL-",B6) -> MSL-B12 | Q6: 618 | R6: =CONCATENATE("DGS-",B6) -> DGS-B12 | S6: 2
A7: 15" Base Cabinet: 1 Door & 1 Drawer | B7: B15 | C7: 677 | D7: =CONCATENATE("ONB-",B7) -> ONB-B15 | E7: 615 | F7: =CONCATENATE("WHS-",B7) -> WHS-B15 | G7: 677 | H7: =CONCATENATE("ESS-",B7) -> ESS-B15 | I7: 677 | J7: =CONCATENATE("SIB-",B7) -> SIB-B15 | K7: 615 | L7: =CONCATENATE("GRS-",B7) -> GRS-B15 | M7: 677 | N7: =CONCATENATE("UPB-",B7) -> UPB-B15 | O7: 677 | P7: =CONCATENATE("MSL-",B7) -> MSL-B15 | Q7: 677 | R7: =CONCATENATE("DGS-",B7) -> DGS-B15 | S7: 2
A8: 18" Base Cabinet: 1 Door & 1 Drawer | B8: B18 | C8: 706 | D8: =CONCATENATE("ONB-",B8) -> ONB-B18 | E8: 642 | F8: =CONCATENATE("WHS-",B8) -> WHS-B18 | G8: 706 | H8: =CONCATENATE("ESS-",B8) -> ESS-B18 | I8: 706 | J8: =CONCATENATE("SIB-",B8) -> SIB-B18 | K8: 642 | L8: =CONCATENATE("GRS-",B8) -> GRS-B18 | M8: 706 | N8: =CONCATENATE("UPB-",B8) -> UPB-B18 | O8: 706 | P8: =CONCATENATE("MSL-",B8) -> MSL-B18 | Q8: 706 | R8: =CONCATENATE("DGS-",B8) -> DGS-B18 | S8: 2
A9: 18" Base Trash Cabinet: 1 Door & 1 Drawer with two 27 qt. Trash Cans | B9: BWBK18-2 | C9: 1311 | D9: =CONCATENATE("ONB-",B9) -> ONB-BWBK18-2 | E9: 1192 | F9: =CONCATENATE("WHS-",B9) -> WHS-BWBK18-2 | G9: 1311 | H9: =CONCATENATE("ESS-",B9) -> ESS-BWBK18-2 | I9: 1311 | J9: =CONCATENATE("SIB-",B9) -> SIB-BWBK18-2 | K9: 1192 | L9: =CONCATENATE("GRS-",B9) -> GRS-BWBK18-2 | M9: 1311 | N9: =CONCATENATE("UPB-",B9) -> UPB-BWBK18-2 | O9: 1311 | P9: =CONCATENATE("MSL-",B9) -> MSL-BWBK18-2 | Q9: 1311 | R9: =CONCATENATE("DGS-",B9) -> DGS-BWBK18-2 | S9: 2
A10: 21" Base Cabinet: 1 Door & 1 Drawer | B10: B21 | C10: 754 | D10: =CONCATENATE("ONB-",B10) -> ONB-B21 | E10: 685 | F10: =CONCATENATE("WHS-",B10) -> WHS-B21 | G10: 754 | H10: =CONCATENATE("ESS-",B10) -> ESS-B21 | I10: 754 | J10: =CONCATENATE("SIB-",B10) -> SIB-B21 | K10: 685 | L10: =CONCATENATE("GRS-",B10) -> GRS-B21 | M10: 754 | N10: =CONCATENATE("UPB-",B10) -> UPB-B21 | O10: 754 | P10: =CONCATENATE("MSL-",B10) -> MSL-B21 | Q10: 754 | R10: =CONCATENATE("DGS-",B10) -> DGS-B21 | S10: 2
A11: 24" Base Cabinet: 2 Doors & 1 Drawer | B11: B24 | C11: 806 | D11: =CONCATENATE("ONB-",B11) -> ONB-B24 | E11: 733 | F11: =CONCATENATE("WHS-",B11) -> WHS-B24 | G11: 806 | H11: =CONCATENATE("ESS-",B11) -> ESS-B24 | I11: 806 | J11: =CONCATENATE("SIB-",B11) -> SIB-B24 | K11: 733 | L11: =CONCATENATE("GRS-",B11) -> GRS-B24 | M11: 806 | N11: =CONCATENATE("UPB-",B11) -> UPB-B24 | O11: 806 | P11: =CONCATENATE("MSL-",B11) -> MSL-B24 | Q11: 806 | R11: =CONCATENATE("DGS-",B11) -> DGS-B24 | S11: 3
A12: 27" Base Cabinet: 2 Doors & 1 Drawer | B12: B27 | C12: 971 | D12: =CONCATENATE("ONB-",B12) -> ONB-B27 | E12: 883 | F12: =CONCATENATE("WHS-",B12) -> WHS-B27 | G12: 971 | H12: =CONCATENATE("ESS-",B12) -> ESS-B27 | I12: 971 | J12: =CONCATENATE("SIB-",B12) -> SIB-B27 | K12: 883 | L12: =CONCATENATE("GRS-",B12) -> GRS-B27 | M12: 971 | N12: =CONCATENATE("UPB-",B12) -> UPB-B27 | O12: 971 | P12: =CONCATENATE("MSL-",B12) -> MSL-B27 | Q12: 971 | R12: =CONCATENATE("DGS-",B12) -> DGS-B27 | S12: 3
A13: 30" Base Cabinet: 2 Doors & 1 Drawer | B13: B30 | C13: 1007 | D13: =CONCATENATE("ONB-",B13) -> ONB-B30 | E13: 915 | F13: =CONCATENATE("WHS-",B13) -> WHS-B30 | G13: 1007 | H13: =CONCATENATE("ESS-",B13) -> ESS-B30 | I13: 1007 | J13: =CONCATENATE("SIB-",B13) -> SIB-B30 | K13: 915 | L13: =CONCATENATE("GRS-",B13) -> GRS-B30 | M13: 1007 | N13: =CONCATENATE("UPB-",B13) -> UPB-B30 | O13: 1007 | P13: =CONCATENATE("MSL-",B13) -> MSL-B30 | Q13: 1007 | R13: =CONCATENATE("DGS-",B13) -> DGS-B30 | S13: 3
A14: 33" Base Cabinet: 2 Doors & 2 Drawers | B14: B33 | C14: 1054 | D14: =CONCATENATE("ONB-",B14) -> ONB-B33 | E14: 958 | F14: =CONCATENATE("WHS-",B14) -> WHS-B33 | G14: 1054 | H14: =CONCATENATE("ESS-",B14) -> ESS-B33 | I14: 1054 | J14: =CONCATENATE("SIB-",B14) -> SIB-B33 | K14: 958 | L14: =CONCATENATE("GRS-",B14) -> GRS-B33 | M14: 1054 | N14: =CONCATENATE("UPB-",B14) -> UPB-B33 | O14: 1054 | P14: =CONCATENATE("MSL-",B14) -> MSL-B33 | Q14: 1054 | R14: =CONCATENATE("DGS-",B14) -> DGS-B33 | S14: 3
A15: 36" Base Cabinet: 2 Doors & 2 Drawers | B15: B36 | C15: 1095 | D15: =CONCATENATE("ONB-",B15) -> ONB-B36 | E15: 995 | F15: =CONCATENATE("WHS-",B15) -> WHS-B36 | G15: 1095 | H15: =CONCATENATE("ESS-",B15) -> ESS-B36 | I15: 1095 | J15: =CONCATENATE("SIB-",B15) -> SIB-B36 | K15: 995 | L15: =CONCATENATE("GRS-",B15) -> GRS-B36 | M15: 1095 | N15: =CONCATENATE("UPB-",B15) -> UPB-B36 | O15: 1095 | P15: =CONCATENATE("MSL-",B15) -> MSL-B36 | Q15: 1095 | R15: =CONCATENATE("DGS-",B15) -> DGS-B36 | S15: 4
A16: 42" Base Cabinet: 2 Doors & 2 Drawers | B16: B42 | C16: 1330 | D16: =CONCATENATE("ONB-",B16) -> ONB-B42 | E16: 1209 | F16: =CONCATENATE("WHS-",B16) -> WHS-B42 | G16: 1330 | H16: =CONCATENATE("ESS-",B16) -> ESS-B42 | I16: 1330 | J16: =CONCATENATE("SIB-",B16) -> SIB-B42 | K16: 1209 | L16: =CONCATENATE("GRS-",B16) -> GRS-B42 | M16: 1330 | N16: =CONCATENATE("UPB-",B16) -> UPB-B42 | O16: 1330 | P16: =CONCATENATE("MSL-",B16) -> MSL-B42 | Q16: 1330 | R16: =CONCATENATE("DGS-",B16) -> DGS-B42 | S16: 4
A17: Base Cabinets with Full Height Door, 24" Depth
A18: 9" Base Cabinet: 1 Full-height Door | B18: B09FHD | C18: 421 | D18: =CONCATENATE("ONB-",B18) -> ONB-B09FHD | E18: 383 | F18: =CONCATENATE("WHS-",B18) -> WHS-B09FHD | G18: 421 | H18: =CONCATENATE("ESS-",B18) -> ESS-B09FHD | I18: 421 | J18: =CONCATENATE("SIB-",B18) -> SIB-B09FHD | K18: 383 | L18: =CONCATENATE("GRS-",B18) -> GRS-B09FHD | M18: 421 | N18: =CONCATENATE("UPB-",B18) -> UPB-B09FHD | O18: 421 | P18: =CONCATENATE("MSL-",B18) -> MSL-B09FHD | Q18: 421 | R18: =CONCATENATE("DGS-",B18) -> DGS-B09FHD | S18: 1
A19: 24" Base Cabinet: 2 Full-height Doors | B19: B24FHD | C19: 751 | D19: =CONCATENATE("ONB-",B19) -> ONB-B24FHD | E19: 683 | F19: =CONCATENATE("WHS-",B19) -> WHS-B24FHD | G19: 751 | H19: =CONCATENATE("ESS-",B19) -> ESS-B24FHD | I19: 751 | J19: =CONCATENATE("SIB-",B19) -> SIB-B24FHD | K19: 683 | L19: =CONCATENATE("GRS-",B19) -> GRS-B24FHD | M19: 751 | N19: =CONCATENATE("UPB-",B19) -> UPB-B24FHD | O19: 751 | P19: =CONCATENATE("MSL-",B19) -> MSL-B24FHD | Q19: 751 | R19: =CONCATENATE("DGS-",B19) -> DGS-B24FHD | S19: 2
A20: 3 Drawer Base Cabinets, 24" Depth
A21: 12" Base Cabinet: 3 Drawers, Drawers are 7", 11" and 11" tall | B21: 3DB12 | C21: 883 | D21: =CONCATENATE("ONB-",B21) -> ONB-3DB12 | E21: 803 | F21: =CONCATENATE("WHS-",B21) -> WHS-3DB12 | G21: 883 | H21: =CONCATENATE("ESS-",B21) -> ESS-3DB12 | I21: 883 | J21: =CONCATENATE("SIB-",B21) -> SIB-3DB12 | K21: 803 | L21: =CONCATENATE("GRS-",B21) -> GRS-3DB12 | M21: 883 | N21: =CONCATENATE("UPB-",B21) -> UPB-3DB12 | O21: 883 | P21: =CONCATENATE("MSL-",B21) -> MSL-3DB12 | Q21: 883 | R21: =CONCATENATE("DGS-",B21) -> DGS-3DB12 | S21: 3
A22: 15" Base Cabinet: 3 Drawers, Drawers are 7", 11" and 11" tall | B22: 3DB15 | C22: 942 | D22: =CONCATENATE("ONB-",B22) -> ONB-3DB15 | E22: 856 | F22: =CONCATENATE("WHS-",B22) -> WHS-3DB15 | G22: 942 | H22: =CONCATENATE("ESS-",B22) -> ESS-3DB15 | I22: 942 | J22: =CONCATENATE("SIB-",B22) -> SIB-3DB15 | K22: 856 | L22: =CONCATENATE("GRS-",B22) -> GRS-3DB15 | M22: 942 | N22: =CONCATENATE("UPB-",B22) -> UPB-3DB15 | O22: 942 | P22: =CONCATENATE("MSL-",B22) -> MSL-3DB15 | Q22: 942 | R22: =CONCATENATE("DGS-",B22) -> DGS-3DB15 | S22: 3
A23: 18" Base Cabinet: 3 Drawers, Drawers are 7", 11" and 11" tall | B23: 3DB18 | C23: 982 | D23: =CONCATENATE("ONB-",B23) -> ONB-3DB18 | E23: 893 | F23: =CONCATENATE("WHS-",B23) -> WHS-3DB18 | G23: 982 | H23: =CONCATENATE("ESS-",B23) -> ESS-3DB18 | I23: 982 | J23: =CONCATENATE("SIB-",B23) -> SIB-3DB18 | K23: 893 | L23: =CONCATENATE("GRS-",B23) -> GRS-3DB18 | M23: 982 | N23: =CONCATENATE("UPB-",B23) -> UPB-3DB18 | O23: 982 | P23: =CONCATENATE("MSL-",B23) -> MSL-3DB18 | Q23: 982 | R23: =CONCATENATE("DGS-",B23) -> DGS-3DB18 | S23: 3
A24: 21" Base Cabinet: 3 Drawers, Drawers are 7", 11" and 11" tall | B24: 3DB21 | C24: 1024 | D24: =CONCATENATE("ONB-",B24) -> ONB-3DB21 | E24: 931 | F24: =CONCATENATE("WHS-",B24) -> WHS-3DB21 | G24: 1024 | H24: =CONCATENATE("ESS-",B24) -> ESS-3DB21 | I24: 1024 | J24: =CONCATENATE("SIB-",B24) -> SIB-3DB21 | K24: 931 | L24: =CONCATENATE("GRS-",B24) -> GRS-3DB21 | M24: 1024 | N24: =CONCATENATE("UPB-",B24) -> UPB-3DB21 | O24: 1024 | P24: =CONCATENATE("MSL-",B24) -> MSL-3DB21 | Q24: 1024 | R24: =CONCATENATE("DGS-",B24) -> DGS-3DB21 | S24: 3
A25: 24" Base Cabinet: 3 Drawers, Drawers are 7", 11" and 11" tall | B25: 3DB24 | C25: 1071 | D25: =CONCATENATE("ONB-",B25) -> ONB-3DB24 | E25: 974 | F25: =CONCATENATE("WHS-",B25) -> WHS-3DB24 | G25: 1071 | H25: =CONCATENATE("ESS-",B25) -> ESS-3DB24 | I25: 1071 | J25: =CONCATENATE("SIB-",B25) -> SIB-3DB24 | K25: 974 | L25: =CONCATENATE("GRS-",B25) -> GRS-3DB24 | M25: 1071 | N25: =CONCATENATE("UPB-",B25) -> UPB-3DB24 | O25: 1071 | P25: =CONCATENATE("MSL-",B25) -> MSL-3DB24 | Q25: 1071 | R25: =CONCATENATE("DGS-",B25) -> DGS-3DB24 | S25: 3
A26: 30" Base Cabinet: 3 Drawers, Drawers are 7", 11" and 11" tall | B26: 3DB30 | C26: 1172 | D26: =CONCATENATE("ONB-",B26) -> ONB-3DB30 | E26: 1065 | F26: =CONCATENATE("WHS-",B26) -> WHS-3DB30 | G26: 1172 | H26: =CONCATENATE("ESS-",B26) -> ESS-3DB30 | I26: 1172 | J26: =CONCATENATE("SIB-",B26) -> SIB-3DB30 | K26: 1065 | L26: =CONCATENATE("GRS-",B26) -> GRS-3DB30 | M26: 1172 | N26: =CONCATENATE("UPB-",B26) -> UPB-3DB30 | O26: 1172 | P26: =CONCATENATE("MSL-",B26) -> MSL-3DB30 | Q26: 1172 | R26: =CONCATENATE("DGS-",B26) -> DGS-3DB30 | S26: 3
A27: 36" Base Cabinet: 3 Drawers, Drawers are 7", 11" and 11" tall | B27: 3DB36 | C27: 1312 | D27: =CONCATENATE("ONB-",B27) -> ONB-3DB36 | E27: 1193 | F27: =CONCATENATE("WHS-",B27) -> WHS-3DB36 | G27: 1312 | H27: =CONCATENATE("ESS-",B27) -> ESS-3DB36 | I27: 1312 | J27: =CONCATENATE("SIB-",B27) -> SIB-3DB36 | K27: 1193 | L27: =CONCATENATE("GRS-",B27) -> GRS-3DB36 | M27: 1312 | N27: =CONCATENATE("UPB-",B27) -> UPB-3DB36 | O27: 1312 | P27: =CONCATENATE("MSL-",B27) -> MSL-3DB36 | Q27: 1312 | R27: =CONCATENATE("DGS-",B27) -> DGS-3DB36 | S27: 3
A28: 2 Drawer Base Cabinets, 24" Depth
A29: 24" Base Cabinet: 2 Drawers, Drawers are 14.5" tall | B29: 2DB24 | C29: 1071 | D29: =CONCATENATE("ONB-",B29) -> ONB-2DB24 | E29: 974 | F29: =CONCATENATE("WHS-",B29) -> WHS-2DB24 | G29: 1071 | H29: =CONCATENATE("ESS-",B29) -> ESS-2DB24 | I29: 1071 | J29: =CONCATENATE("SIB-",B29) -> SIB-2DB24 | K29: 974 | L29: =CONCATENATE("GRS-",B29) -> GRS-2DB24 | M29: 1071 | N29: =CONCATENATE("UPB-",B29) -> UPB-2DB24 | O29: 1071 | P29: =CONCATENATE("MSL-",B29) -> MSL-2DB24 | Q29: 1071 | R29: =CONCATENATE("DGS-",B29) -> DGS-2DB24 | S29: 2
A30: 30" Base Cabinet: 2 Drawers, Drawers are 14.5" tall | B30: 2DB30 | C30: 1172 | D30: =CONCATENATE("ONB-",B30) -> ONB-2DB30 | E30: 1065 | F30: =CONCATENATE("WHS-",B30) -> WHS-2DB30 | G30: 1172 | H30: =CONCATENATE("ESS-",B30) -> ESS-2DB30 | I30: 1172 | J30: =CONCATENATE("SIB-",B30) -> SIB-2DB30 | K30: 1065 | L30: =CONCATENATE("GRS-",B30) -> GRS-2DB30 | M30: 1172 | N30: =CONCATENATE("UPB-",B30) -> UPB-2DB30 | O30: 1172 | P30: =CONCATENATE("MSL-",B30) -> MSL-2DB30 | Q30: 1172 | R30: =CONCATENATE("DGS-",B30) -> DGS-2DB30 | S30: 2
A31: 36" Base Cabinet: 2 Drawers, Drawers are 14.5" tall | B31: 2DB36 | C31: 1312 | D31: =CONCATENATE("ONB-",B31) -> ONB-2DB36 | E31: 1193 | F31: =CONCATENATE("WHS-",B31) -> WHS-2DB36 | G31: 1312 | H31: =CONCATENATE("ESS-",B31) -> ESS-2DB36 | I31: 1312 | J31: =CONCATENATE("SIB-",B31) -> SIB-2DB36 | K31: 1193 | L31: =CONCATENATE("GRS-",B31) -> GRS-2DB36 | M31: 1312 | N31: =CONCATENATE("UPB-",B31) -> UPB-2DB36 | O31: 1312 | P31: =CONCATENATE("MSL-",B31) -> MSL-2DB36 | Q31: 1312 | R31: =CONCATENATE("DGS-",B31) -> DGS-2DB36 | S31: 2
A32: Sink Base Cabinets, 24" Depth
A33: 30" Base Cabinet: 2 Doors & 1 False Drawer | B33: SB30 | C33: 741 | D33: =CONCATENATE("ONB-",B33) -> ONB-SB30 | E33: 674 | F33: =CONCATENATE("WHS-",B33) -> WHS-SB30 | G33: 741 | H33: =CONCATENATE("ESS-",B33) -> ESS-SB30 | I33: 741 | J33: =CONCATENATE("SIB-",B33) -> SIB-SB30 | K33: 674 | L33: =CONCATENATE("GRS-",B33) -> GRS-SB30 | M33: 741 | N33: =CONCATENATE("UPB-",B33) -> UPB-SB30 | O33: 741 | P33: =CONCATENATE("MSL-",B33) -> MSL-SB30 | Q33: 741 | R33: =CONCATENATE("DGS-",B33) -> DGS-SB30 | S33: 2
A34: 33" Base Cabinet: 2 Doors & 1 False Drawer | B34: SB33 | C34: 794 | D34: =CONCATENATE("ONB-",B34) -> ONB-SB33 | E34: 722 | F34: =CONCATENATE("WHS-",B34) -> WHS-SB33 | G34: 794 | H34: =CONCATENATE("ESS-",B34) -> ESS-SB33 | I34: 794 | J34: =CONCATENATE("SIB-",B34) -> SIB-SB33 | K34: 722 | L34: =CONCATENATE("GRS-",B34) -> GRS-SB33 | M34: 794 | N34: =CONCATENATE("UPB-",B34) -> UPB-SB33 | O34: 794 | P34: =CONCATENATE("MSL-",B34) -> MSL-SB33 | Q34: 794 | R34: =CONCATENATE("DGS-",B34) -> DGS-SB33 | S34: 2
A35: 36" Base Cabinet: 2 Doors & 2 False Drawers | B35: SB36 | C35: 812 | D35: =CONCATENATE("ONB-",B35) -> ONB-SB36 | E35: 738 | F35: =CONCATENATE("WHS-",B35) -> WHS-SB36 | G35: 812 | H35: =CONCATENATE("ESS-",B35) -> ESS-SB36 | I35: 812 | J35: =CONCATENATE("SIB-",B35) -> SIB-SB36 | K35: 738 | L35: =CONCATENATE("GRS-",B35) -> GRS-SB36 | M35: 812 | N35: =CONCATENATE("UPB-",B35) -> UPB-SB36 | O35: 812 | P35: =CONCATENATE("MSL-",B35) -> MSL-SB36 | Q35: 812 | R35: =CONCATENATE("DGS-",B35) -> DGS-SB36 | S35: 2
A36: 42" Base Cabinet: 2 Doors & 2 False Drawers | B36: SB42 | C36: 883 | D36: =CONCATENATE("ONB-",B36) -> ONB-SB42 | E36: 803 | F36: =CONCATENATE("WHS-",B36) -> WHS-SB42 | G36: 883 | H36: =CONCATENATE("ESS-",B36) -> ESS-SB42 | I36: 883 | J36: =CONCATENATE("SIB-",B36) -> SIB-SB42 | K36: 803 | L36: =CONCATENATE("GRS-",B36) -> GRS-SB42 | M36: 883 | N36: =CONCATENATE("UPB-",B36) -> UPB-SB42 | O36: 883 | P36: =CONCATENATE("MSL-",B36) -> MSL-SB42 | Q36: 883 | R36: =CONCATENATE("DGS-",B36) -> DGS-SB42 | S36: 2
A37: Farm Sink Base Cabinet, 24" Depth
A38: 36" Base Cabinet: 2 Doors & 33" W x 10" Opening for Sink | B38: FSM36 | C38: 880 | D38: =CONCATENATE("ONB-",B38) -> ONB-FSM36 | E38: 800 | F38: =CONCATENATE("WHS-",B38) -> WHS-FSM36 | G38: 880 | H38: =CONCATENATE("ESS-",B38) -> ESS-FSM36 | I38: 880 | J38: =CONCATENATE("SIB-",B38) -> SIB-FSM36 | K38: 800 | L38: =CONCATENATE("GRS-",B38) -> GRS-FSM36 | M38: 880 | N38: =CONCATENATE("UPB-",B38) -> UPB-FSM36 | O38: 880 | P38: =CONCATENATE("MSL-",B38) -> MSL-FSM36 | Q38: 880 | R38: =CONCATENATE("DGS-",B38) -> DGS-FSM36 | S38: 2
A39: Corner Sink Base Cabinet, 24" Depth
A40: 42" Base Cabinet: 1 24" Door, fits in a 42" x 42" corner space | B40: CSB42 | C40: 982 | D40: =CONCATENATE("ONB-",B40) -> ONB-CSB42 | E40: 893 | F40: =CONCATENATE("WHS-",B40) -> WHS-CSB42 | G40: 982 | H40: =CONCATENATE("ESS-",B40) -> ESS-CSB42 | I40: 982 | J40: =CONCATENATE("SIB-",B40) -> SIB-CSB42 | K40: 893 | L40: =CONCATENATE("GRS-",B40) -> GRS-CSB42 | M40: 982 | N40: =CONCATENATE("UPB-",B40) -> UPB-CSB42 | O40: 982 | P40: =CONCATENATE("MSL-",B40) -> MSL-CSB42 | Q40: 982 | R40: =CONCATENATE("DGS-",B40) -> DGS-CSB42 | S40: 2
A41: Corner Base Cabinets, 24" Depth
...

Sheet Framed Accessory List Price
C2: ONYX BLACK | E2: WHITE SHAKER | G2: ESPRESSO SHAKER | I2: SIGNATURE BLUE | K2: Gray Shaker | M2: Uptown White | O2: Modern Slate | Q2: Dark Green Slim Shaker
C3: ONB | E3: WHS | G3: ESS | I3: SIB | K3: GRS | M3: UPB | O3: MSL | Q3: DGS
A4: Description | B4: Accessory Name | C4: List Price | D4: Inventory Code | E4: List Price | F4: Inventory Code | G4: List Price | H4: Inventory Code | I4: List Price | J4: Inventory Code | K4: List Price | L4: Inventory Code | M4: List Price | N4: Inventory Code | O4: List Price | P4: Inventory Code | Q4: List Price | R4: Inventory Code
A5: 1/4" Cabinet Skins:
A6: Wall Cabinet Skin: 12" W x 30" H | B6: DEP12*30*1/4 | C6: 47 | D6: =CONCATENATE("ONB-",B6,) -> ONB-DEP12*30*1/4 | E6: 45 | F6: =CONCATENATE("WHS-",B6,) -> WHS-DEP12*30*1/4 | G6: 47 | H6: =CONCATENATE("ESS-",B6,) -> ESS-DEP12*30*1/4 | I6: 47 | J6: =CONCATENATE("SIB-",B6) -> SIB-DEP12*30*1/4 | K6: 45 | L6: =CONCATENATE("GRS-",B6,) -> GRS-DEP12*30*1/4 | M6: 47 | N6: =CONCATENATE("UPB-",B6,) -> UPB-DEP12*30*1/4 | O6: 47 | P6: =CONCATENATE("MSL-",B6,) -> MSL-DEP12*30*1/4 | Q6: 47 | R6: =CONCATENATE("DGS-",B6,) -> DGS-DEP12*30*1/4
A7: Wall Cabinet Skin: 12" W x 36" H | B7: DEP12*36*1/4 | C7: 53 | D7: =CONCATENATE("ONB-",B7,) -> ONB-DEP12*36*1/4 | E7: 50 | F7: =CONCATENATE("WHS-",B7,) -> WHS-DEP12*36*1/4 | G7: 53 | H7: =CONCATENATE("ESS-",B7,) -> ESS-DEP12*36*1/4 | I7: 53 | J7: =CONCATENATE("SIB-",B7) -> SIB-DEP12*36*1/4 | K7: 50 | L7: =CONCATENATE("GRS-",B7,) -> GRS-DEP12*36*1/4 | M7: 53 | N7: =CONCATENATE("UPB-",B7,) -> UPB-DEP12*36*1/4 | O7: 53 | P7: =CONCATENATE("MSL-",B7,) -> MSL-DEP12*36*1/4 | Q7: 53 | R7: =CONCATENATE("DGS-",B7,) -> DGS-DEP12*36*1/4
A8: Wall Cabinet Skin: 12" W x 42" H | B8: DEP12*42*1/4 | C8: 58 | D8: =CONCATENATE("ONB-",B8,) -> ONB-DEP12*42*1/4 | E8: 55 | F8: =CONCATENATE("WHS-",B8,) -> WHS-DEP12*42*1/4 | G8: 58 | H8: =CONCATENATE("ESS-",B8,) -> ESS-DEP12*42*1/4 | I8: 58 | J8: =CONCATENATE("SIB-",B8) -> SIB-DEP12*42*1/4 | K8: 55 | L8: =CONCATENATE("GRS-",B8,) -> GRS-DEP12*42*1/4 | M8: 58 | N8: =CONCATENATE("UPB-",B8,) -> UPB-DEP12*42*1/4 | O8: 58 | P8: =CONCATENATE("MSL-",B8,) -> MSL-DEP12*42*1/4 | Q8: 58 | R8: =CONCATENATE("DGS-",B8,) -> DGS-DEP12*42*1/4
A9: Base Cabinet Skin: 21" W x 34.5" H | B9: DEP21*34.5*1/4 | C9: 79 | D9: =CONCATENATE("ONB-",B9,) -> ONB-DEP21*34.5*1/4 | E9: 75 | F9: =CONCATENATE("WHS-",B9,) -> WHS-DEP21*34.5*1/4 | G9: 79 | H9: =CONCATENATE("ESS-",B9,) -> ESS-DEP21*34.5*1/4 | I9: 79 | J9: =CONCATENATE("SIB-",B9) -> SIB-DEP21*34.5*1/4 | K9: 75 | L9: =CONCATENATE("GRS-",B9,) -> GRS-DEP21*34.5*1/4 | M9: 79 | N9: =CONCATENATE("UPB-",B9,) -> UPB-DEP21*34.5*1/4 | O9: 79 | P9: =CONCATENATE("MSL-",B9,) -> MSL-DEP21*34.5*1/4 | Q9: 79 | R9: =CONCATENATE("DGS-",B9,) -> DGS-DEP21*34.5*1/4
A10: Base Cabinet Skin: 24" W x 34.5" H | B10: DEP24*34.5*1/4 | C10: 89 | D10: =CONCATENATE("ONB-",B10,) -> ONB-DEP24*34.5*1/4 | E10: 85 | F10: =CONCATENATE("WHS-",B10,) -> WHS-DEP24*34.5*1/4 | G10: 89 | H10: =CONCATENATE("ESS-",B10,) -> ESS-DEP24*34.5*1/4 | I10: 89 | J10: =CONCATENATE("SIB-",B10) -> SIB-DEP24*34.5*1/4 | K10: 85 | L10: =CONCATENATE("GRS-",B10,) -> GRS-DEP24*34.5*1/4 | M10: 89 | N10: =CONCATENATE("UPB-",B10,) -> UPB-DEP24*34.5*1/4 | O10: 89 | P10: =CONCATENATE("MSL-",B10,) -> MSL-DEP24*34.5*1/4 | Q10: 89 | R10: =CONCATENATE("DGS-",B10,) -> DGS-DEP24*34.5*1/4
A11: Pantry Cabinet Skin: 24" W x 96" H | B11: DEP24*96*1/4 | C11: 184 | D11: =CONCATENATE("ONB-",B11,) -> ONB-DEP24*96*1/4 | E11: 175 | F11: =CONCATENATE("WHS-",B11,) -> WHS-DEP24*96*1/4 | G11: 184 | H11: =CONCATENATE("ESS-",B11,) -> ESS-DEP24*96*1/4 | I11: 184 | J11: =CONCATENATE("SIB-",B11) -> SIB-DEP24*96*1/4 | K11: 175 | L11: =CONCATENATE("GRS-",B11,) -> GRS-DEP24*96*1/4 | M11: 184 | N11: =CONCATENATE("UPB-",B11,) -> UPB-DEP24*96*1/4 | O11: 184 | P11: =CONCATENATE("MSL-",B11,) -> MSL-DEP24*96*1/4 | Q11: 184 | R11: =CONCATENATE("DGS-",B11,) -> DGS-DEP24*96*1/4
A12: 1/4" Cabinet Panel: 34.5" W x 96" H | B12: PNL 34.5*96*1/4 | C12: 336 | D12: =CONCATENATE("ONB-",B12,) -> ONB-PNL 34.5*96*1/4 | E12: 321 | F12: =CONCATENATE("WHS-",B12,) -> WHS-PNL 34.5*96*1/4 | G12: 336 | H12: =CONCATENATE("ESS-",B12,) -> ESS-PNL 34.5*96*1/4 | I12: 336 | J12: =CONCATENATE("SIB-",B12) -> SIB-PNL 34.5*96*1/4 | K12: 321 | L12: =CONCATENATE("GRS-",B12,) -> GRS-PNL 34.5*96*1/4 | M12: 336 | N12: =CONCATENATE("UPB-",B12,) -> UPB-PNL 34.5*96*1/4 | O12: 336 | P12: =CONCATENATE("MSL-",B12,) -> MSL-PNL 34.5*96*1/4 | Q12: 336 | R12: =CONCATENATE("DGS-",B12,) -> DGS-PNL 34.5*96*1/4
A13: 1/2" Cabinet Panels:
A14: Island Back Panel: 34.5" W x 96" H | B14: PNL34.5*96*1/2-VERTICAL | C14: 375 | D14: =CONCATENATE("ONB-",B14,) -> ONB-PNL34.5*96*1/2-VERTICAL | E14: 350 | F14: =CONCATENATE("WHS-",B14,) -> WHS-PNL34.5*96*1/2-VERTICAL | G14: 375 | H14: =CONCATENATE("ESS-",B14,) -> ESS-PNL34.5*96*1/2-VERTICAL | I14: 375 | J14: =CONCATENATE("SIB-",B14) -> SIB-PNL34.5*96*1/2-VERTICAL | K14: 350 | L14: =CONCATENATE("GRS-",B14,) -> GRS-PNL34.5*96*1/2-VERTICAL | M14: 375 | N14: =CONCATENATE("UPB-",B14,) -> UPB-PNL34.5*96*1/2-VERTICAL | O14: 375 | P14: =CONCATENATE("MSL-",B14,) -> MSL-PNL34.5*96*1/2-VERTICAL | Q14: 375 | R14: =CONCATENATE("DGS-",B14,) -> DGS-PNL34.5*96*1/2-VERTICAL
A15: Dishwasher Return Panel: 24" W x 34.5" H, 3" Return filler included | B15: DWR3 | C15: 130 | D15: =CONCATENATE("ONB-",B15,) -> ONB-DWR3 | E15: 123 | F15: =CONCATENATE("WHS-",B15) -> WHS-DWR3 | G15: 130 | H15: =CONCATENATE("ESS-",B15) -> ESS-DWR3 | I15: 130 | J15: =CONCATENATE("SIB-",B15) -> SIB-DWR3 | K15: 123.05 | L15: =CONCATENATE("GRS-",B15,) -> GRS-DWR3 | M15: 130 | N15: =CONCATENATE("UPB-",B15,) -> UPB-DWR3 | O15: 130 | P15: =CONCATENATE("MSL-",B15,) -> MSL-DWR3 | Q15: 130 | R15: =CONCATENATE("DGS-",B15,) -> DGS-DWR3
A16: Refrigerator Return Panel: 24" W x 96" H, 1.5" return filler included | B16: REP1.5x96 | C16: 435 | D16: =CONCATENATE("ONB-",B16,) -> ONB-REP1.5x96 | E16: 425 | F16: =CONCATENATE("WHS-",B16) -> WHS-REP1.5x96 | G16: 435 | H16: =CONCATENATE("ESS-",B16) -> ESS-REP1.5x96 | I16: 435 | J16: =CONCATENATE("SIB-",B16) -> SIB-REP1.5x96 | K16: 425 | L16: =CONCATENATE("GRS-",B16,) -> GRS-REP1.5x96 | M16: 435 | N16: =CONCATENATE("UPB-",B16,) -> UPB-REP1.5x96 | O16: 435 | P16: =CONCATENATE("MSL-",B16,) -> MSL-REP1.5x96 | Q16: 435 | R16: =CONCATENATE("DGS-",B16,) -> DGS-REP1.5x96
A17: Refrigerator Return Panel: 24" W x 96" H, 3" return filler included | B17: REP3x96 | C17: 480 | D17: =CONCATENATE("ONB-",B17,) -> ONB-REP3x96 | E17: 467 | F17: =CONCATENATE("WHS-",B17) -> WHS-REP3x96 | G17: 480 | H17: =CONCATENATE("ESS-",B17) -> ESS-REP3x96 | I17: 480 | J17: =CONCATENATE("SIB-",B17) -> SIB-REP3x96 | K17: 467 | L17: =CONCATENATE("GRS-",B17,) -> GRS-REP3x96 | M17: 480 | N17: =CONCATENATE("UPB-",B17,) -> UPB-REP3x96 | O17: 480 | P17: =CONCATENATE("MSL-",B17,) -> MSL-REP3x96 | Q17: 480 | R17: =CONCATENATE("DGS-",B17,) -> DGS-REP3x96
A18: Cabinet Fillers, 3/4" Thick:
A19: Base Cabinet Filler: 3" W x 30" H | B19: BF3 | C19: 67 | D19: =CONCATENATE("ONB-",B19,) -> ONB-BF3 | E19: 64 | F19: =CONCATENATE("WHS-",B19,) -> WHS-BF3 | G19: 67 | H19: =CONCATENATE("ESS-",B19,) -> ESS-BF3 | I19: 67 | J19: =CONCATENATE("SIB-",B19) -> SIB-BF3 | K19: 64.2 | L19: =CONCATENATE("GRS-",B19,) -> GRS-BF3 | M19: 67 | N19: =CONCATENATE("UPB-",B19,) -> UPB-BF3 | O19: 67 | P19: =CONCATENATE("MSL-",B19,) -> MSL-BF3 | Q19: 67 | R19: =CONCATENATE("DGS-",B19,) -> DGS-BF3
A20: Base Cabinet Filler: 6" W x 30" H | B20: BF6 | C20: 123 | D20: =CONCATENATE("ONB-",B20,) -> ONB-BF6 | E20: 118 | F20: =CONCATENATE("WHS-",B20,) -> WHS-BF6 | G20: 123 | H20: =CONCATENATE("ESS-",B20,) -> ESS-BF6 | I20: 123 | J20: =CONCATENATE("SIB-",B20) -> SIB-BF6 | K20: 117.7 | L20: =CONCATENATE("GRS-",B20,) -> GRS-BF6 | M20: 123 | N20: =CONCATENATE("UPB-",B20,) -> UPB-BF6 | O20: 123 | P20: =CONCATENATE("MSL-",B20,) -> MSL-BF6 | Q20: 123 | R20: =CONCATENATE("DGS-",B20,) -> DGS-BF6
A21: Wall Cabinet Filler: 3" W x 30" H | B21: WF330 | C21: 45 | D21: =CONCATENATE("ONB-",B21,) -> ONB-WF330 | E21: 43 | F21: =CONCATENATE("WHS-",B21,) -> WHS-WF330 | G21: 45 | H21: =CONCATENATE("ESS-",B21,) -> ESS-WF330 | I21: 45 | J21: =CONCATENATE("SIB-",B21) -> SIB-WF330 | K21: 42.8 | L21: =CONCATENATE("GRS-",B21,) -> GRS-WF330 | M21: 45 | N21: =CONCATENATE("UPB-",B21,) -> UPB-WF330 | O21: 45 | P21: =CONCATENATE("MSL-",B21,) -> MSL-WF330 | Q21: 45 | R21: =CONCATENATE("DGS-",B21,) -> DGS-WF330
A22: Wall Cabinet Filler: 3" W x 36" H | B22: WF336 | C22: 50 | D22: =CONCATENATE("ONB-",B22,) -> ONB-WF336 | E22: 48 | F22: =CONCATENATE("WHS-",B22,) -> WHS-WF336 | G22: 50 | H22: =CONCATENATE("ESS-",B22,) -> ESS-WF336 | I22: 50 | J22: =CONCATENATE("SIB-",B22) -> SIB-WF336 | K22: 48.15 | L22: =CONCATENATE("GRS-",B22,) -> GRS-WF336 | M22: 50 | N22: =CONCATENATE("UPB-",B22,) -> UPB-WF336 | O22: 50 | P22: =CONCATENATE("MSL-",B22,) -> MSL-WF336 | Q22: 50 | R22: =CONCATENATE("DGS-",B22,) -> DGS-WF336
A23: Wall Cabinet Filler: 3" W x 42" H | B23: WF342 | C23: 59 | D23: =CONCATENATE("ONB-",B23,) -> ONB-WF342 | E23: 57 | F23: =CONCATENATE("WHS-",B23,) -> WHS-WF342 | G23: 59 | H23: =CONCATENATE("ESS-",B23,) -> ESS-WF342 | I23: 59 | J23: =CONCATENATE("SIB-",B23) -> SIB-WF342 | K23: 56.71 | L23: =CONCATENATE("GRS-",B23,) -> GRS-WF342 | M23: 59 | N23: =CONCATENATE("UPB-",B23,) -> UPB-WF342 | O23: 59 | P23: =CONCATENATE("MSL-",B23,) -> MSL-WF342 | Q23: 59 | R23: =CONCATENATE("DGS-",B23,) -> DGS-WF342
A24: Wall (Tall) Cabinet Filler: 3" W x 96" H | B24: WF396 | C24: 136 | D24: =CONCATENATE("ONB-",B24,) -> ONB-WF396 | E24: 130 | F24: =CONCATENATE("WHS-",B24,) -> WHS-WF396 | G24: 136 | H24: =CONCATENATE("ESS-",B24,) -> ESS-WF396 | I24: 136 | J24: =CONCATENATE("SIB-",B24) -> SIB-WF396 | K24: 129.47 | L24: =CONCATENATE("GRS-",B24,) -> GRS-WF396 | M24: 136 | N24: =CONCATENATE("UPB-",B24,) -> UPB-WF396 | O24: 136 | P24: =CONCATENATE("MSL-",B24,) -> MSL-WF396 | Q24: 136 | R24: =CONCATENATE("DGS-",B24,) -> DGS-WF396
A25: Wall Cabinet Filler: 6" W x 30" H | B25: WF630 | C25: 78 | D25: =CONCATENATE("ONB-",B25,) -> ONB-WF630 | E25: 75 | F25: =CONCATENATE("WHS-",B25,) -> WHS-WF630 | G25: 78 | H25: =CONCATENATE("ESS-",B25,) -> ESS-WF630 | I25: 78 | J25: =CONCATENATE("SIB-",B25) -> SIB-WF630 | K25: 74.9 | L25: =CONCATENATE("GRS-",B25,) -> GRS-WF630 | M25: 78 | N25: =CONCATENATE("UPB-",B25,) -> UPB-WF630 | O25: 78 | P25: =CONCATENATE("MSL-",B25,) -> MSL-WF630 | Q25: 78 | R25: =CONCATENATE("DGS-",B25,) -> DGS-WF630
A26: Wall Cabinet Filler: 6" W x 36" H | B26: WF636 | C26: 90 | D26: =CONCATENATE("ONB-",B26,) -> ONB-WF636 | E26: 86 | F26: =CONCATENATE("WHS-",B26,) -> WHS-WF636 | G26: 90 | H26: =CONCATENATE("ESS-",B26,) -> ESS-WF636 | I26: 90 | J26: =CONCATENATE("SIB-",B26) -> SIB-WF636 | K26: 85.6 | L26: =CONCATENATE("GRS-",B26,) -> GRS-WF636 | M26: 90 | N26: =CONCATENATE("UPB-",B26,) -> UPB-WF636 | O26: 90 | P26: =CONCATENATE("MSL-",B26,) -> MSL-WF636 | Q26: 90 | R26: =CONCATENATE("DGS-",B26,) -> DGS-WF636
A27: Wall Cabinet Filler: 6" W x 42" H | B27: WF642 | C27: 118 | D27: =CONCATENATE("ONB-",B27,) -> ONB-WF642 | E27: 112 | F27: =CONCATENATE("WHS-",B27,) -> WHS-WF642 | G27: 118 | H27: =CONCATENATE("ESS-",B27,) -> ESS-WF642 | I27: 118 | J27: =CONCATENATE("SIB-",B27) -> SIB-WF642 | K27: 112.35 | L27: =CONCATENATE("GRS-",B27,) -> GRS-WF642 | M27: 118 | N27: =CONCATENATE("UPB-",B27,) -> UPB-WF642 | O27: 118 | P27: =CONCATENATE("MSL-",B27,) -> MSL-WF642 | Q27: 118 | R27: =CONCATENATE("DGS-",B27,) -> DGS-WF642
A28: Wall (Tall) Cabinet Filler: 6" W x 96" H | B28: WF696 | C28: 272 | D28: =CONCATENATE("ONB-",B28,) -> ONB-WF696 | E28: 260 | F28: =CONCATENATE("WHS-",B28,) -> WHS-WF696 | G28: 272 | H28: =CONCATENATE("ESS-",B28,) -> ESS-WF696 | I28: 272 | J28: =CONCATENATE("SIB-",B28) -> SIB-WF696 | K28: 260.01 | L28: =CONCATENATE("GRS-",B28,) -> GRS-WF696 | M28: 272 | N28: =CONCATENATE("UPB-",B28,) -> UPB-WF696 | O28: 272 | P28: =CONCATENATE("MSL-",B28,) -> MSL-WF696 | Q28: 272 | R28: =CONCATENATE("DGS-",B28,) -> DGS-WF696
A29: Tall Filler: 1.5" W x 96" H, includes dado for use as return | B29: TF1.5*96 | C29: 67 | D29: =CONCATENATE("ONB-",B29,) -> ONB-TF1.5*96 | E29: 64 | F29: =CONCATENATE("WHS-",B29,) -> WHS-TF1.5*96 | G29: 67 | H29: =CONCATENATE("ESS-",B29,) -> ESS-TF1.5*96 | I29: 67 | J29: =CONCATENATE("SIB-",B29) -> SIB-TF1.5*96 | K29: 64.2 | L29: =CONCATENATE("GRS-",B29,) -> GRS-TF1.5*96 | M29: 67 | N29: =CONCATENATE("UPB-",B29,) -> UPB-TF1.5*96 | O29: 67 | P29: =CONCATENATE("MSL-",B29,) -> MSL-TF1.5*96 | Q29: 67 | R29: =CONCATENATE("DGS-",B29,) -> DGS-TF1.5*96
A30: Tall Filler: 3" W x 96" H | B30: TF396 | C30: 134 | D30: =CONCATENATE("ONB-",B30,) -> ONB-TF396 | E30: 129 | F30: =CONCATENATE("WHS-",B30,) -> WHS-TF396 | G30: 134 | H30: =CONCATENATE("ESS-",B30,) -> ESS-TF396 | I30: 134 | J30: =CONCATENATE("SIB-",B30) -> SIB-TF396 | K30: 128.4 | L30: =CONCATENATE("GRS-",B30,) -> GRS-TF396 | M30: 134 | N30: =CONCATENATE("UPB-",B30,) -> UPB-TF396 | O30: 134 | P30: =CONCATENATE("MSL-",B30,) -> MSL-TF396 | Q30: 134 | R30: =CONCATENATE("DGS-",B30,) -> DGS-TF396
A31: Tall Filler: 6" W x 96" H | B31: TF696 | C31: 224 | D31: =CONCATENATE("ONB-",B31,) -> ONB-TF696 | E31: 214 | F31: =CONCATENATE("WHS-",B31,) -> WHS-TF696 | G31: 224 | H31: =CONCATENATE("ESS-",B31,) -> ESS-TF696 | I31: 224 | J31: =CONCATENATE("SIB-",B31) -> SIB-TF696 | K31: 214 | L31: =CONCATENATE("GRS-",B31,) -> GRS-TF696 | M31: 224 | N31: =CONCATENATE("UPB-",B31,) -> UPB-TF696 | O31: 224 | P31: =CONCATENATE("MSL-",B31,) -> MSL-TF696 | Q31: 224 | R31: =CONCATENATE("DGS-",B31,) -> DGS-TF696
A32: Molding, 96" Length:
A33: Scribe Molding: 3/4" Tall & 1/4" Thick, Rounded on one edge | B33: SM8 | C33: 37 | D33: =CONCATENATE("ONB-",B33,) -> ONB-SM8 | E33: 35 | F33: =CONCATENATE("WHS-",B33,) -> WHS-SM8 | G33: 37 | H33: =CONCATENATE("ESS-",B33,) -> ESS-SM8 | I33: 37 | J33: =CONCATENATE("SIB-",B33) -> SIB-SM8 | K33: 35.31 | L33: =CONCATENATE("GRS-",B33,) -> GRS-SM8 | M33: 37 | N33: =CONCATENATE("UPB-",B33,) -> UPB-SM8 | O33: 37 | P33: =CONCATENATE("MSL-",B33,) -> MSL-SM8 | Q33: 37 | R33: =CONCATENATE("DGS-",B33,) -> DGS-SM8
A34: Batten Molding: 3/4" Tall & 1/4" Thick, Rounded on two edges | B34: SDM8 | C34: 44 | D34: =CONCATENATE("ONB-",B34,) -> ONB-SDM8 | E34: 42 | F34: =CONCATENATE("WHS-",B34,) -> WHS-SDM8 | G34: 44 | H34: =CONCATENATE("ESS-",B34,) -> ESS-SDM8 | I34: 44 | J34: =CONCATENATE("SIB-",B34) -> SIB-SDM8 | K34: 42 | L34: =CONCATENATE("GRS-",B34,) -> GRS-SDM8 | M34: 44 | N34: =CONCATENATE("UPB-",B34,) -> UPB-SDM8 | O34: 44 | P34: =CONCATENATE("MSL-",B34,) -> MSL-SDM8 | Q34: 44 | R34: =CONCATENATE("DGS-",B34,) -> DGS-SDM8
A35: Cove Molding: 3/4" Tall | B35: Cove Molding | C35: 112 | D35: =CONCATENATE("ONB-",B35,) -> ONB-Cove Molding | E35: 107 | F35: =CONCATENATE("WHS-",B35,) -> WHS-Cove Molding | G35: 112 | H35: =CONCATENATE("ESS-",B35,) -> ESS-Cove Molding | I35: 112 | J35: =CONCATENATE("SIB-",B35) -> SIB-Cove Molding | K35: 107 | L35: =CONCATENATE("GRS-",B35,) -> GRS-Cove Molding | M35: 112 | N35: =CONCATENATE("UPB-",B35,) -> UPB-Cove Molding | O35: 112 | P35: =CONCATENATE("MSL-",B35,) -> MSL-Cove Molding | Q35: 112 | R35: =CONCATENATE("DGS-",B35,) -> DGS-Cove Molding
A36: Outside Corner Molding: 3/4" x 3/4" | B36: OCM8 | C36: 75 | D36: =CONCATENATE("ONB-",B36,) -> ONB-OCM8 | E36: 72 | F36: =CONCATENATE("WHS-",B36,) -> WHS-OCM8 | G36: 75 | H36: =CONCATENATE("ESS-",B36,) -> ESS-OCM8 | I36: 75 | J36: =CONCATENATE("SIB-",B36) -> SIB-OCM8 | K36: 71.69 | L36: =CONCATENATE("GRS-",B36,) -> GRS-OCM8 | M36: 75 | N36: =CONCATENATE("UPB-",B36,) -> UPB-OCM8 | O36: 75 | P36: =CONCATENATE("MSL-",B36,) -> MSL-OCM8 | Q36: 75 | R36: =CONCATENATE("DGS-",B36,) -> DGS-OCM8
A37: Light Rail Molding: 1 1/2" Tall | B37: LM8 | C37: 106 | D37: =CONCATENATE("ONB-",B37,) -> ONB-LM8 | E37: 102 | F37: =CONCATENATE("WHS-",B37,) -> WHS-LM8 | G37: 106 | H37: =CONCATENATE("ESS-",B37,) -> ESS-LM8 | I37: 106 | J37: =CONCATENATE("SIB-",B37) -> SIB-LM8 | K37: 101.65 | L37: =CONCATENATE("GRS-",B37,) -> GRS-LM8 | M37: 106 | N37: =CONCATENATE("UPB-",B37,) -> UPB-LM8 | O37: 106 | P37: =CONCATENATE("MSL-",B37,) -> MSL-LM8 | Q37: 106 | R37: =CONCATENATE("DGS-",B37,) -> DGS-LM8
A38: Quarter Round Molding: 3/4" x 3/4" | B38: QRM8 | C38: 67 | D38: =CONCATENATE("ONB-",B38,) -> ONB-QRM8 | E38: 64 | F38: =CONCATENATE("WHS-",B38,) -> WHS-QRM8 | G38: 67 | H38: =CONCATENATE("ESS-",B38,) -> ESS-QRM8 | I38: 67 | J38: =CONCATENATE("SIB-",B38) -> SIB-QRM8 | K38: 64.2 | L38: =CONCATENATE("GRS-",B38,) -> GRS-QRM8 | M38: 67 | N38: =CONCATENATE("UPB-",B38,) -> UPB-QRM8 | O38: 67 | P38: =CONCATENATE("MSL-",B38,) -> MSL-QRM8 | Q38: 67 | R38: =CONCATENATE("DGS-",B38,) -> DGS-QRM8
A39: Crown Molding: Rises 2 1/4" tall from cabinet | B39: SCM2 1/4 | C39: 171 | D39: =CONCATENATE("ONB-",B39,) -> ONB-SCM2 1/4 | E39: 107 | F39: =CONCATENATE("WHS-",B39,) -> WHS-SCM2 1/4 | G39: 171 | H39: =CONCATENATE("ESS-",B39,) -> ESS-SCM2 1/4 | I39: 171 | J39: =CONCATENATE("SIB-",B39) -> SIB-SCM2 1/4 | K39: 107 | L39: =CONCATENATE("GRS-",B39,) -> GRS-SCM2 1/4 | M39: 171 | N39: =CONCATENATE("UPB-",B39,) -> UPB-SCM2 1/4 | O39: 171 | P39: =CONCATENATE("MSL-",B39,) -> MSL-SCM2 1/4 | Q39: 171 | R39: =CONCATENATE("DGS-",B39,) -> DGS-SCM2 1/4
A40: Crown Molding: Rises 2 1/4" tall from cabinet | B40: SCM2 1/4-HEEL | C40: N/A | D40: =CONCATENATE("ONB-",B40,) -> ONB-SCM2 1/4-HEEL | E40: 144 | F40: =CONCATENATE("WHS-",B40,) -> WHS-SCM2 1/4-HEEL | G40: N/A | H40: =CONCATENATE("ESS-",B40,) -> ESS-SCM2 1/4-HEEL | I40: N/A | J40: =CONCATENATE("SIB-",B40) -> SIB-SCM2 1/4-HEEL | K40: N/A | L40: =CONCATENATE("GRS-",B40,) -> GRS-SCM2 1/4-HEEL | M40: 214 | N40: =CONCATENATE("UPB-",B40,) -> UPB-SCM2 1/4-HEEL | O40: N/A | P40: =CONCATENATE("MSL-",B40,) -> MSL-SCM2 1/4-HEEL | Q40: N/A | R40: =CONCATENATE("DGS-",B40,) -> DGS-SCM2 1/4-HEEL
A41: Crown Molding: Rises 3 5/8" tall from cabinet | B41: SCM3 5/8 | C41: 198 | D41: =CONCATENATE("ONB-",B41,) -> ONB-SCM3 5/8 | E41: 127 | F41: =CONCATENATE("WHS-",B41,) -> WHS-SCM3 5/8 | G41: 198 | H41: =CONCATENATE("ESS-",B41,) -> ESS-SCM3 5/8 | I41: 198 | J41: =CONCATENATE("SIB-",B41) -> SIB-SCM3 5/8 | K41: 127 | L41: =CONCATENATE("GRS-",B41,) -> GRS-SCM3 5/8 | M41: 198 | N41: =CONCATENATE("UPB-",B41,) -> UPB-SCM3 5/8 | O41: 198 | P41: =CONCATENATE("MSL-",B41,) -> MSL-SCM3 5/8 | Q41: 198 | R41: =CONCATENATE("DGS-",B41,) -> DGS-SCM3 5/8
...

Sheet Frameless Catalog List Price
C2: GLOSSY WHITE | E2: SLICED OAK SHAKER | G2: BLACK WALNUT | I2: WEATHERED OAK SHAKER | K2: GLOSSY GREY | M2: NATURAL OAK | O2: WHITE OAK | Q2: MATTE WHITE | S2: MATTE GREY | U2: MATTE BLUE | W2: GLOSSY BLACK
A3: Description | B3: Cabinet Name | C3: List Price | D3: Inventory Code | E3: List Price | F3: Inventory Code | G3: List Price | H3: Inventory Code | I3: List Price | J3: Inventory Code | K3: List Price | L3: Inventory Code | M3: List Price | N3: Inventory Code | O3: List Price | P3: Inventory Code | Q3: List Price | R3: Inventory Code | S3: List Price | T3: Inventory Code | U3: List Price | V3: Inventory Code | W3: List Price | X3: Inventory Code | Y3: Handles
A4: Base Cabinets with Drawer, 24" Depth
A5: 12" Base Cabinet: 1 Door & 1 Drawer | B5: B12 | C5: =IF('Summary Sheet'!$M$4="Plywood",VLOOKUP($B5,'Pwood & PB List'!$B$4:$V$158,9,FALSE),IF('Summary Sheet'!$M$4="PB w/ Wood Drawers",VLOOKUP($B5,'Pwood & PB List'!$B$4:$V$158,13,FALSE),IF('Summary Sheet'!$M$4="PB w/ PB Drawers",VLOOKUP($B5,'Pwood & PB List'!$B$4:$V$158,17,FALSE)))) -> 747.5 | D5: =CONCATENATE("GLW-",B5) -> GLW-B12 | E5: =IF('Summary Sheet'!$M$4="Plywood",VLOOKUP($B5,'Pwood & PB List'!$B$4:$V$158,10,FALSE),IF('Summary Sheet'!$M$4="PB w/ Wood Drawers",VLOOKUP($B5,'Pwood & PB List'!$B$4:$V$158,14,FALSE),IF('Summary Sheet'!$M$4="PB w/ PB Drawers",VLOOKUP($B5,'Pwood & PB List'!$B$4:$V$158,18,FALSE)))) -> 729.33 | F5: =CONCATENATE("SLO-",B5) -> SLO-B12 | G5: =IF('Summary Sheet'!$M$4="Plywood",VLOOKUP($B5,'Pwood & PB List'!$B$4:$V$158,11,FALSE),IF('Summary Sheet'!$M$4="PB w/ Wood Drawers",VLOOKUP($B5,'Pwood & PB List'!$B$4:$V$158,15,FALSE),IF('Summary Sheet'!$M$4="PB w/ PB Drawers",VLOOKUP($B5,'Pwood & PB List'!$B$4:$V$158,19,FALSE)))) -> 709.895 | H5: =CONCATENATE("BLW-",B5) -> BLW-B12 | I5: =IF('Summary Sheet'!$M$4="Plywood",VLOOKUP($B5,'Pwood & PB List'!$B$4:$V$158,10,FALSE),IF('Summary Sheet'!$M$4="PB w/ Wood Drawers",VLOOKUP($B5,'Pwood & PB List'!$B$4:$V$158,14,FALSE),IF('Summary Sheet'!$M$4="PB w/ PB Drawers",VLOOKUP($B5,'Pwood & PB List'!$B$4:$V$158,18,FALSE)))) -> 729.33 | J5: =CONCATENATE("WEO-",B5) -> WEO-B12 | K5: =IF('Summary Sheet'!$M$4="Plywood",VLOOKUP($B5,'Pwood & PB List'!$B$4:$V$158,9,FALSE),IF('Summary Sheet'!$M$4="PB w/ Wood Drawers",VLOOKUP($B5,'Pwood & PB List'!$B$4:$V$158,13,FALSE),IF('Summary Sheet'!$M$4="PB w/ PB Drawers",VLOOKUP($B5,'Pwood & PB List'!$B$4:$V$158,17,FALSE)))) -> 747.5 | L5: =CONCATENATE("GLG-",B5) -> GLG-B12 | M5: =IF('Summary Sheet'!$M$4="Plywood",VLOOKUP($B5,'Pwood & PB List'!$B$4:$V$158,12,FALSE),IF('Summary Sheet'!$M$4="PB w/ Wood Drawers",VLOOKUP($B5,'Pwood & PB List'!$B$4:$V$158,16,FALSE),IF('Summary Sheet'!$M$4="PB w/ PB Drawers",VLOOKUP($B5,'Pwood & PB List'!$B$4:$V$158,20,FALSE)))) -> 688.16 | N5: =CONCATENATE("NAO-",B5) -> NAO-B12 | O5: =IF('Summary Sheet'!$M$4="Plywood",VLOOKUP($B5,'Pwood & PB List'!$B$4:$V$158,12,FALSE),IF('Summary Sheet'!$M$4="PB w/ Wood Drawers",VLOOKUP($B5,'Pwood & PB List'!$B$4:$V$158,16,FALSE),IF('Summary Sheet'!$M$4="PB w/ PB Drawers",VLOOKUP($B5,'Pwood & PB List'!$B$4:$V$158,20,FALSE)))) -> 688.16 | P5: =CONCATENATE("WHO-",B5) -> WHO-B12 | Q5: =IF('Summary Sheet'!$M$4="Plywood",VLOOKUP($B5,'Pwood & PB List'!$B$4:$V$158,9,FALSE),IF('Summary Sheet'!$M$4="PB w/ Wood Drawers",VLOOKUP($B5,'Pwood & PB List'!$B$4:$V$158,13,FALSE),IF('Summary Sheet'!$M$4="PB w/ PB Drawers",VLOOKUP($B5,'Pwood & PB List'!$B$4:$V$158,17,FALSE)))) -> 747.5 | R5: =CONCATENATE("MAW-",B5) -> MAW-B12 | S5: =IF('Summary Sheet'!$M$4="Plywood",VLOOKUP($B5,'Pwood & PB List'!$B$4:$V$158,9,FALSE),IF('Summary Sheet'!$M$4="PB w/ Wood Drawers",VLOOKUP($B5,'Pwood & PB List'!$B$4:$V$158,13,FALSE),IF('Summary Sheet'!$M$4="PB w/ PB Drawers",VLOOKUP($B5,'Pwood & PB List'!$B$4:$V$158,17,FALSE)))) -> 747.5 | T5: =CONCATENATE("MAG-",B5) -> MAG-B12 | U5: =IF('Summary Sheet'!$M$4="Plywood",VLOOKUP($B5,'Pwood & PB List'!$B$4:$V$158,9,FALSE),IF('Summary Sheet'!$M$4="PB w/ Wood Drawers",VLOOKUP($B5,'Pwood & PB List'!$B$4:$V$158,13,FALSE),IF('Summary Sheet'!$M$4="PB w/ PB Drawers",VLOOKUP($B5,'Pwood & PB List'!$B$4:$V$158,17,FALSE)))) -> 747.5 | V5: =CONCATENATE("MAB-",B5) -> MAB-B12 | W5: =IF('Summary Sheet'!$M$4="Plywood",VLOOKUP($B5,'Pwood & PB List'!$B$4:$V$158,9,FALSE),IF('Summary Sheet'!$M$4="PB w/ Wood Drawers",VLOOKUP($B5,'Pwood & PB List'!$B$4:$V$158,13,FALSE),IF('Summary Sheet'!$M$4="PB w/ PB Drawers",VLOOKUP($B5,'Pwood & PB List'!$B$4:$V$158,17,FALSE)))) -> 747.5 | X5: =CONCATENATE("GLB-",B5) -> GLB-B12 | Y5: 2
A6: 15" Base Cabinet: 1 Door & 1 Drawer | B6: B15 | C6: =IF('Summary Sheet'!$M$4="Plywood",VLOOKUP($B6,'Pwood & PB List'!$B$4:$V$158,9,FALSE),IF('Summary Sheet'!$M$4="PB w/ Wood Drawers",VLOOKUP($B6,'Pwood & PB List'!$B$4:$V$158,13,FALSE),IF('Summary Sheet'!$M$4="PB w/ PB Drawers",VLOOKUP($B6,'Pwood & PB List'!$B$4:$V$158,17,FALSE)))) -> 828.23 | D6: =CONCATENATE("GLW-",B6) -> GLW-B15 | E6: =IF('Summary Sheet'!$M$4="Plywood",VLOOKUP($B6,'Pwood & PB List'!$B$4:$V$158,10,FALSE),IF('Summary Sheet'!$M$4="PB w/ Wood Drawers",VLOOKUP($B6,'Pwood & PB List'!$B$4:$V$158,14,FALSE),IF('Summary Sheet'!$M$4="PB w/ PB Drawers",VLOOKUP($B6,'Pwood & PB List'!$B$4:$V$158,18,FALSE)))) -> 805.46 | F6: =CONCATENATE("SLO-",B6) -> SLO-B15 | G6: =IF('Summary Sheet'!$M$4="Plywood",VLOOKUP($B6,'Pwood & PB List'!$B$4:$V$158,11,FALSE),IF('Summary Sheet'!$M$4="PB w/ Wood Drawers",VLOOKUP($B6,'Pwood & PB List'!$B$4:$V$158,15,FALSE),IF('Summary Sheet'!$M$4="PB w/ PB Drawers",VLOOKUP($B6,'Pwood & PB List'!$B$4:$V$158,19,FALSE)))) -> 781.195 | H6: =CONCATENATE("BLW-",B6) -> BLW-B15 | I6: =IF('Summary Sheet'!$M$4="Plywood",VLOOKUP($B6,'Pwood & PB List'!$B$4:$V$158,10,FALSE),IF('Summary Sheet'!$M$4="PB w/ Wood Drawers",VLOOKUP($B6,'Pwood & PB List'!$B$4:$V$158,14,FALSE),IF('Summary Sheet'!$M$4="PB w/ PB Drawers",VLOOKUP($B6,'Pwood & PB List'!$B$4:$V$158,18,FALSE)))) -> 805.46 | J6: =CONCATENATE("WEO-",B6) -> WEO-B15 | K6: =IF('Summary Sheet'!$M$4="Plywood",VLOOKUP($B6,'Pwood & PB List'!$B$4:$V$158,9,FALSE),IF('Summary Sheet'!$M$4="PB w/ Wood Drawers",VLOOKUP($B6,'Pwood & PB List'!$B$4:$V$158,13,FALSE),IF('Summary Sheet'!$M$4="PB w/ PB Drawers",VLOOKUP($B6,'Pwood & PB List'!$B$4:$V$158,17,FALSE)))) -> 828.23 | L6: =CONCATENATE("GLG-",B6) -> GLG-B15 | M6: =IF('Summary Sheet'!$M$4="Plywood",VLOOKUP($B6,'Pwood & PB List'!$B$4:$V$158,12,FALSE),IF('Summary Sheet'!$M$4="PB w/ Wood Drawers",VLOOKUP($B6,'Pwood & PB List'!$B$4:$V$158,16,FALSE),IF('Summary Sheet'!$M$4="PB w/ PB Drawers",VLOOKUP($B6,'Pwood & PB List'!$B$4:$V$158,20,FALSE)))) -> 753.825 | N6: =CONCATENATE("NAO-",B6) -> NAO-B15 | O6: =IF('Summary Sheet'!$M$4="Plywood",VLOOKUP($B6,'Pwood & PB List'!$B$4:$V$158,12,FALSE),IF('Summary Sheet'!$M$4="PB w/ Wood Drawers",VLOOKUP($B6,'Pwood & PB List'!$B$4:$V$158,16,FALSE),IF('Summary Sheet'!$M$4="PB w/ PB Drawers",VLOOKUP($B6,'Pwood & PB List'!$B$4:$V$158,20,FALSE)))) -> 753.825 | P6: =CONCATENATE("WHO-",B6) -> WHO-B15 | Q6: =IF('Summary Sheet'!$M$4="Plywood",VLOOKUP($B6,'Pwood & PB List'!$B$4:$V$158,9,FALSE),IF('Summary Sheet'!$M$4="PB w/ Wood Drawers",VLOOKUP($B6,'Pwood & PB List'!$B$4:$V$158,13,FALSE),IF('Summary Sheet'!$M$4="PB w/ PB Drawers",VLOOKUP($B6,'Pwood & PB List'!$B$4:$V$158,17,FALSE)))) -> 828.23 | R6: =CONCATENATE("MAW-",B6) -> MAW-B15 | S6: =IF('Summary Sheet'!$M$4="Plywood",VLOOKUP($B6,'Pwood & PB List'!$B$4:$V$158,9,FALSE),IF('Summary Sheet'!$M$4="PB w/ Wood Drawers",VLOOKUP($B6,'Pwood & PB List'!$B$4:$V$158,13,FALSE),IF('Summary Sheet'!$M$4="PB w/ PB Drawers",VLOOKUP($B6,'Pwood & PB List'!$B$4:$V$158,17,FALSE)))) -> 828.23 | T6: =CONCATENATE("MAG-",B6) -> MAG-B15 | U6: =IF('Summary Sheet'!$M$4="Plywood",VLOOKUP($B6,'Pwood & PB List'!$B$4:$V$158,9,FALSE),IF('Summary Sheet'!$M$4="PB w/ Wood Drawers",VLOOKUP($B6,'Pwood & PB List'!$B$4:$V$158,13,FALSE),IF('Summary Sheet'!$M$4="PB w/ PB Drawers",VLOOKUP($B6,'Pwood & PB List'!$B$4:$V$158,17,FALSE)))) -> 828.23 | V6: =CONCATENATE("MAB-",B6) -> MAB-B15 | W6: =IF('Summary Sheet'!$M$4="Plywood",VLOOKUP($B6,'Pwood & PB List'!$B$4:$V$158,9,FALSE),IF('Summary Sheet'!$M$4="PB w/ Wood Drawers",VLOOKUP($B6,'Pwood & PB List'!$B$4:$V$158,13,FALSE),IF('Summary Sheet'!$M$4="PB w/ PB Drawers",VLOOKUP($B6,'Pwood & PB List'!$B$4:$V$158,17,FALSE)))) -> 828.23 | X6: =CONCATENATE("GLB-",B6) -> GLB-B15 | Y6: 2
A7: 18" Base Cabinet: 1 Door & 1 Drawer | B7: B18 | C7: =IF('Summary Sheet'!$M$4="Plywood",VLOOKUP($B7,'Pwood & PB List'!$B$4:$V$158,9,FALSE),IF('Summary Sheet'!$M$4="PB w/ Wood Drawers",VLOOKUP($B7,'Pwood & PB List'!$B$4:$V$158,13,FALSE),IF('Summary Sheet'!$M$4="PB w/ PB Drawers",VLOOKUP($B7,'Pwood & PB List'!$B$4:$V$158,17,FALSE)))) -> 908.845 | D7: =CONCATENATE("GLW-",B7) -> GLW-B18 | E7: =IF('Summary Sheet'!$M$4="Plywood",VLOOKUP($B7,'Pwood & PB List'!$B$4:$V$158,10,FALSE),IF('Summary Sheet'!$M$4="PB w/ Wood Drawers",VLOOKUP($B7,'Pwood & PB List'!$B$4:$V$158,14,FALSE),IF('Summary Sheet'!$M$4="PB w/ PB Drawers",VLOOKUP($B7,'Pwood & PB List'!$B$4:$V$158,18,FALSE)))) -> 881.59 | F7: =CONCATENATE("SLO-",B7) -> SLO-B18 | G7: =IF('Summary Sheet'!$M$4="Plywood",VLOOKUP($B7,'Pwood & PB List'!$B$4:$V$158,11,FALSE),IF('Summary Sheet'!$M$4="PB w/ Wood Drawers",VLOOKUP($B7,'Pwood & PB List'!$B$4:$V$158,15,FALSE),IF('Summary Sheet'!$M$4="PB w/ PB Drawers",VLOOKUP($B7,'Pwood & PB List'!$B$4:$V$158,19,FALSE)))) -> 852.38 | H7: =CONCATENATE("BLW-",B7) -> BLW-B18 | I7: =IF('Summary Sheet'!$M$4="Plywood",VLOOKUP($B7,'Pwood & PB List'!$B$4:$V$158,10,FALSE),IF('Summary Sheet'!$M$4="PB w/ Wood Drawers",VLOOKUP($B7,'Pwood & PB List'!$B$4:$V$158,14,FALSE),IF('Summary Sheet'!$M$4="PB w/ PB Drawers",VLOOKUP($B7,'Pwood & PB List'!$B$4:$V$158,18,FALSE)))) -> 881.59 | J7: =CONCATENATE("WEO-",B7) -> WEO-B18 | K7: =IF('Summary Sheet'!$M$4="Plywood",VLOOKUP($B7,'Pwood & PB List'!$B$4:$V$158,9,FALSE),IF('Summary Sheet'!$M$4="PB w/ Wood Drawers",VLOOKUP($B7,'Pwood & PB List'!$B$4:$V$158,13,FALSE),IF('Summary Sheet'!$M$4="PB w/ PB Drawers",VLOOKUP($B7,'Pwood & PB List'!$B$4:$V$158,17,FALSE)))) -> 908.845 | L7: =CONCATENATE("GLG-",B7) -> GLG-B18 | M7: =IF('Summary Sheet'!$M$4="Plywood",VLOOKUP($B7,'Pwood & PB List'!$B$4:$V$158,12,FALSE),IF('Summary Sheet'!$M$4="PB w/ Wood Drawers",VLOOKUP($B7,'Pwood & PB List'!$B$4:$V$158,16,FALSE),IF('Summary Sheet'!$M$4="PB w/ PB Drawers",VLOOKUP($B7,'Pwood & PB List'!$B$4:$V$158,20,FALSE)))) -> 819.605 | N7: =CONCATENATE("NAO-",B7) -> NAO-B18 | O7: =IF('Summary Sheet'!$M$4="Plywood",VLOOKUP($B7,'Pwood & PB List'!$B$4:$V$158,12,FALSE),IF('Summary Sheet'!$M$4="PB w/ Wood Drawers",VLOOKUP($B7,'Pwood & PB List'!$B$4:$V$158,16,FALSE),IF('Summary Sheet'!$M$4="PB w/ PB Drawers",VLOOKUP($B7,'Pwood & PB List'!$B$4:$V$158,20,FALSE)))) -> 819.605 | P7: =CONCATENATE("WHO-",B7) -> WHO-B18 | Q7: =IF('Summary Sheet'!$M$4="Plywood",VLOOKUP($B7,'Pwood & PB List'!$B$4:$V$158,9,FALSE),IF('Summary Sheet'!$M$4="PB w/ Wood Drawers",VLOOKUP($B7,'Pwood & PB List'!$B$4:$V$158,13,FALSE),IF('Summary Sheet'!$M$4="PB w/ PB Drawers",VLOOKUP($B7,'Pwood & PB List'!$B$4:$V$158,17,FALSE)))) -> 908.845 | R7: =CONCATENATE("MAW-",B7) -> MAW-B18 | S7: =IF('Summary Sheet'!$M$4="Plywood",VLOOKUP($B7,'Pwood & PB List'!$B$4:$V$158,9,FALSE),IF('Summary Sheet'!$M$4="PB w/ Wood Drawers",VLOOKUP($B7,'Pwood & PB List'!$B$4:$V$158,13,FALSE),IF('Summary Sheet'!$M$4="PB w/ PB Drawers",VLOOKUP($B7,'Pwood & PB List'!$B$4:$V$158,17,FALSE)))) -> 908.845 | T7: =CONCATENATE("MAG-",B7) -> MAG-B18 | U7: =IF('Summary Sheet'!$M$4="Plywood",VLOOKUP($B7,'Pwood & PB List'!$B$4:$V$158,9,FALSE),IF('Summary Sheet'!$M$4="PB w/ Wood Drawers",VLOOKUP($B7,'Pwood & PB List'!$B$4:$V$158,13,FALSE),IF('Summary Sheet'!$M$4="PB w/ PB Drawers",VLOOKUP($B7,'Pwood & PB List'!$B$4:$V$158,17,FALSE)))) -> 908.845 | V7: =CONCATENATE("MAB-",B7) -> MAB-B18 | W7: =IF('Summary Sheet'!$M$4="Plywood",VLOOKUP($B7,'Pwood & PB List'!$B$4:$V$158,9,FALSE),IF('Summary Sheet'!$M$4="PB w/ Wood Drawers",VLOOKUP($B7,'Pwood & PB List'!$B$4:$V$158,13,FALSE),IF('Summary Sheet'!$M$4="PB w/ PB Drawers",VLOOKUP($B7,'Pwood & PB List'!$B$4:$V$158,17,FALSE)))) -> 908.845 | X7: =CONCATENATE("GLB-",B7) -> GLB-B18 | Y7: 2
A8: 18" Base Trash Cabinet: 1 Door & 1 Drawer With Trash Can Pullout | B8: BTC18 | C8: =IF('Summary Sheet'!$M$4="Plywood",VLOOKUP($B8,'Pwood & PB List'!$B$4:$V$158,9,FALSE),IF('Summary Sheet'!$M$4="PB w/ Wood Drawers",VLOOKUP($B8,'Pwood & PB List'!$B$4:$V$158,13,FALSE),IF('Summary Sheet'!$M$4="PB w/ PB Drawers",VLOOKUP($B8,'Pwood & PB List'!$B$4:$V$158,17,FALSE)))) -> 1358.495 | D8: =CONCATENATE("GLW-",B8) -> GLW-BTC18 | E8: =IF('Summary Sheet'!$M$4="Plywood",VLOOKUP($B8,'Pwood & PB List'!$B$4:$V$158,10,FALSE),IF('Summary Sheet'!$M$4="PB w/ Wood Drawers",VLOOKUP($B8,'Pwood & PB List'!$B$4:$V$158,14,FALSE),IF('Summary Sheet'!$M$4="PB w/ PB Drawers",VLOOKUP($B8,'Pwood & PB List'!$B$4:$V$158,18,FALSE)))) -> 1331.24 | F8: =CONCATENATE("SLO-",B8) -> SLO-BTC18 | G8: =IF('Summary Sheet'!$M$4="Plywood",VLOOKUP($B8,'Pwood & PB List'!$B$4:$V$158,11,FALSE),IF('Summary Sheet'!$M$4="PB w/ Wood Drawers",VLOOKUP($B8,'Pwood & PB List'!$B$4:$V$158,15,FALSE),IF('Summary Sheet'!$M$4="PB w/ PB Drawers",VLOOKUP($B8,'Pwood & PB List'!$B$4:$V$158,19,FALSE)))) -> 1302.03 | H8: =CONCATENATE("BLW-",B8) -> BLW-BTC18 | I8: =IF('Summary Sheet'!$M$4="Plywood",VLOOKUP($B8,'Pwood & PB List'!$B$4:$V$158,10,FALSE),IF('Summary Sheet'!$M$4="PB w/ Wood Drawers",VLOOKUP($B8,'Pwood & PB List'!$B$4:$V$158,14,FALSE),IF('Summary Sheet'!$M$4="PB w/ PB Drawers",VLOOKUP($B8,'Pwood & PB List'!$B$4:$V$158,18,FALSE)))) -> 1331.24 | J8: =CONCATENATE("WEO-",B8) -> WEO-BTC18 | K8: =IF('Summary Sheet'!$M$4="Plywood",VLOOKUP($B8,'Pwood & PB List'!$B$4:$V$158,9,FALSE),IF('Summary Sheet'!$M$4="PB w/ Wood Drawers",VLOOKUP($B8,'Pwood & PB List'!$B$4:$V$158,13,FALSE),IF('Summary Sheet'!$M$4="PB w/ PB Drawers",VLOOKUP($B8,'Pwood & PB List'!$B$4:$V$158,17,FALSE)))) -> 1358.495 | L8: =CONCATENATE("GLG-",B8) -> GLG-BTC18 | M8: =IF('Summary Sheet'!$M$4="Plywood",VLOOKUP($B8,'Pwood & PB List'!$B$4:$V$158,12,FALSE),IF('Summary Sheet'!$M$4="PB w/ Wood Drawers",VLOOKUP($B8,'Pwood & PB List'!$B$4:$V$158,16,FALSE),IF('Summary Sheet'!$M$4="PB w/ PB Drawers",VLOOKUP($B8,'Pwood & PB List'!$B$4:$V$158,20,FALSE)))) -> 1269.255 | N8: =CONCATENATE("NAO-",B8) -> NAO-BTC18 | O8: =IF('Summary Sheet'!$M$4="Plywood",VLOOKUP($B8,'Pwood & PB List'!$B$4:$V$158,12,FALSE),IF('Summary Sheet'!$M$4="PB w/ Wood Drawers",VLOOKUP($B8,'Pwood & PB List'!$B$4:$V$158,16,FALSE),IF('Summary Sheet'!$M$4="PB w/ PB Drawers",VLOOKUP($B8,'Pwood & PB List'!$B$4:$V$158,20,FALSE)))) -> 1269.255 | P8: =CONCATENATE("WHO-",B8) -> WHO-BTC18 | Q8: =IF('Summary Sheet'!$M$4="Plywood",VLOOKUP($B8,'Pwood & PB List'!$B$4:$V$158,9,FALSE),IF('Summary Sheet'!$M$4="PB w/ Wood Drawers",VLOOKUP($B8,'Pwood & PB List'!$B$4:$V$158,13,FALSE),IF('Summary Sheet'!$M$4="PB w/ PB Drawers",VLOOKUP($B8,'Pwood & PB List'!$B$4:$V$158,17,FALSE)))) -> 1358.495 | R8: =CONCATENATE("MAW-",B8) -> MAW-BTC18 | S8: =IF('Summary Sheet'!$M$4="Plywood",VLOOKUP($B8,'Pwood & PB List'!$B$4:$V$158,9,FALSE),IF('Summary Sheet'!$M$4="PB w/ Wood Drawers",VLOOKUP($B8,'Pwood & PB List'!$B$4:$V$158,13,FALSE),IF('Summary Sheet'!$M$4="PB w/ PB Drawers",VLOOKUP($B8,'Pwood & PB List'!$B$4:$V$158,17,FALSE)))) -> 1358.495 | T8: =CONCATENATE("MAG-",B8) -> MAG-BTC18 | U8: =IF('Summary Sheet'!$M$4="Plywood",VLOOKUP($B8,'Pwood & PB List'!$B$4:$V$158,9,FALSE),IF('Summary Sheet'!$M$4="PB w/ Wood Drawers",VLOOKUP($B8,'Pwood & PB List'!$B$4:$V$158,13,FALSE),IF('Summary Sheet'!$M$4="PB w/ PB Drawers",VLOOKUP($B8,'Pwood & PB List'!$B$4:$V$158,17,FALSE)))) -> 1358.495 | V8: =CONCATENATE("MAB-",B8) -> MAB-BTC18 | W8: =IF('Summary Sheet'!$M$4="Plywood",VLOOKUP($B8,'Pwood & PB List'!$B$4:$V$158,9,FALSE),IF('Summary Sheet'!$M$4="PB w/ Wood Drawers",VLOOKUP($B8,'Pwood & PB List'!$B$4:$V$158,13,FALSE),IF('Summary Sheet'!$M$4="PB w/ PB Drawers",VLOOKUP($B8,'Pwood & PB List'!$B$4:$V$158,17,FALSE)))) -> 1358.495 | X8: =CONCATENATE("GLB-",B8) -> GLB-BTC18 | Y8: 2
